Workbook

Sheet COMANDI
A1: NOME COMANDO | B1: CODICE CMD H (hex) | C1: CODICE CMD L (hex) | D1: DATI AGGIUNTIVI
A2: Versione protocollo | B2: 0 | C2: 0
A3: Versione protocollo risposta | B3: 80 | C3: 0 | D3: VersioneH | E3: VersioneL
A4: Leggi variabile logica | B4: 0 | C4: 1 | D4: IndirizzoH | E4: IndirizzoL
A5: Leggi variabile logica risposta | B5: 80 | C5: 1 | D5: IndirizzoH | E5: IndirizzoL | F5: Valori di dimensione come da dizionario dati
A6: Scrivi variabile logica | B6: 0 | C6: 2 | D6: IndirizzoH | E6: IndirizzoL | F6: Valori di dimensione come da dizionario dati
A7: Scrivi variabile logica risposta | B7: 80 | C7: 2 | D7: IndirizzoH | E7: IndirizzoL
A8: Leggi range di variabili | B8: 0 | C8: 3 | D8: IndirizzoInizialeH | E8: IndirizzoInizialeL | F8: NumeroVariabiliH | G8: NumeroVariabiliL
A9: Leggi range di variabili risposta | B9: 80 | C9: 3 | D9: IndirizzoInizialeH | E9: IndirizzoInizialeL | F9: NumeroVariabiliH | G9: NumeroVariabiliH | H9: Valori di dimensione come da NumeroVariabiliHL
A10: Scrivi area di memoria fisica | B10: 0 | C10: 4 | D10: IndirizzoH | E10: IndirizzoL | F10: DimensioneArrayH | G10: DimensioneArrayL | H10: Valori di dimensione come da DimensioneArrayHL
A11: Scrivi area di memoria fisica risposta | B11: 80 | C11: 4 | D11: IndirizzoH | E11: IndirizzoL | F11: DimensioneArrayH | G11: DimensioneArrayL
A12: Bootloader avvio procedura | B12: 0 | C12: 5
A13: Bootloader avvio procedura risposta | B13: 80 | C13: 5 | D13: Risultato (0 = ok, != 0 codice errore)
A14: Bootloader fine procedura | B14: 0 | C14: 6
A15: Bootloader fine procedura risposta | B15: 80 | C15: 6 | D15: Risultato (0 = ok, != 0 codice errore)
A16: Bootloader update pagina di memoria | B16: 0 | C16: 7 | D16: FwTypeH | E16: FwTypeL | F16: NumeroPaginaHH | G16: NumeroPaginaHL | H16: NumeroPaginaLH | I16: NumeroPaginaLL | J16: DimensionePaginaHH | K16: DimensionePaginaHL | L16: DimensionePaginaLH | M16: DimensionePaginaLL | N16: ReservedHH | O16: ReservedHL | P16: ReservedLH | Q16: ReservedLL | R16: Valori di dimensione come da DimensionePaginaHL
A17: Bootloader update pagina di memoria risposta | B17: 80 | C17: 7 | D17: FwTypeH | E17: FwTypeL | F17: NumeroPaginaHH | G17: NumeroPaginaHL | H17: NumeroPaginaLH | I17: NumeroPaginaLL | J17: DimensionePaginaHH | K17: DimensionePaginaHL | L17: DimensionePaginaLH | M17: DimensionePaginaLL | N17: ReservedHH | O17: ReservedHL | P17: ReservedLH | Q17: ReservedLL | R17: Risultato (0=ok, !=0 codice errore)
A18: Avvia macchina | B18: 0 | C18: 8
A19: Avvia macchina risposta | B19: 80 | C19: 8 | D19: Risultato (0 = ok, != 0 codice errore)
A20: Ferma macchina | B20: 0 | C20: 9
A21: Ferma macchina risposta | B21: 80 | C21: 9 | D21: Risultato (0 = ok, != 0 codice errore)
A22: Riavvio dispositivo | B22: 0 | C22: A
A23: Riavvio dispositivo risposta | B23: 80 | C23: A
A24: Unlock caratteristica BLE | B24: 0 | C24: B
A25: Lock caratteristica BLE | B25: 0 | C25: C
A26: Up da telecomando | B26: 0 | C26: D | D26: Stato (0 = rilasciato, 1 = premuto) | E26: BatteryVolts
A27: Down da telecomando | B27: 0 | C27: E | D27: Stato (0 = rilasciato, 1 = premuto) | E27: BatteryVolts
A28: Inizio Apprendimento | B28: 0 | C28: F
A29: Inizio Apprendimento Risposta | B29: 80 | C29: F | D29: Risultato (0 = ok, != 0 codice errore)
A30: Salva Posizione | B30: 0 | C30: 10 | D30: Direzione (1 = scarico, 2 = carico, 3=entrambe) | E30: Fermati? (0 = no, 1 = si)
A31: Salva Posizione Risposta | B31: 80 | C31: 10 | D31: Risultato (0 = ok, != 0 codice errore)
A32: Fine Apprendimento | B32: 0 | C32: 11
A33: Fine Apprendimento Risposta | B33: 80 | C33: 11 | D33: Risultato (0 = ok, != 0 codice errore)
A34: Comanda Piano | B34: 0 | C34: 12 | D34: Muovi (0 = no, 1 = si) | E34: AngoloHH | F34: AngoloH | G34: AngoloLH | H34: AngoloLL
A35: Comanda Piano Risposta | B35: 80 | C35: 12 | D35: Risultato (0 = ok, != 0 non può muoversi)
A36: Abilita pairing mode client BLE | B36: 0 | C36: 13 | D36: Device Name[0] | E36: Device Name[1] | F36: Device Name[2] | G36: Device Name[3] | H36: Device Name[4] | I36: Device Name[5] | J36: Device Name[6] | K36: Device Name[7] | L36: Device Name[8] | M36: Device Name[9]
A37: Disabilita pairing mode client BLE | B37: 0 | C37: 14
A38: Imposta telemetria | B38: 0 | C38: 15 | D38: Tipo telemetria HH: il tipo è un codice univoco deciso dall'amministratore tramite portale all'atto del configurare la telemetria e viene usato per la decodifica dei dati binari | E38: Tipo telemetria HL | F38: Tipo telemetria LH | G38: Tipo telemetria LL | H38: Istanza telemetria: una macchina può gestire più istanze di telemetria | I38: Periodo ms H | J38: Periodo ms L | K38: Indirizzo Scheda LH | L38: Indirizzo Scheda LL | M38: Indirizzo Logico Begin H | N38: Indirizzo Logico Begin L | O38: Indirizzo Logico End H | P38: Indirizzo Logico End L
A39: Imposta telemetria Risposta | B39: 80 | C39: 15
A40: Start telemetria | B40: 0 | C40: 16 | D40: Istanza telemetria
...

Sheet ESEMPI MESSAGGI COMANDI BLE
B3: 17 | C3: 0x24 | D3: 0x00 | E3: 0x41 | F3: 0x02 | G3: 0x06 | H3: 0x00 | I3: 0x00 | J3: 0x00 | K3: 0x05 | L3: 0x01 | M3: 0xC1 | N3: 0x00 | O3: 0x02 | P3: 0x00 | Q3: 0x0B | R3: 0xF7 | S3: 0x83
B4: 17 | C4: 0x24 | D4: 0x00 | E4: 0x41 | F4: 0x02 | G4: 0x06 | H4: 0x00 | I4: 0x00 | J4: 0x00 | K4: 0x05 | L4: 0x01 | M4: 0xC1 | N4: 0x00 | O4: 0x02 | P4: 0x00 | Q4: 0x0C | R4: 0x35 | S4: 0xC2
B5: 17 | C5: 0x24 | D5: 0x00 | E5: 0x41 | F5: 0x02 | G5: 0x06 | H5: 0x00 | I5: 0x00 | J5: 0x00 | K5: 0x05 | L5: 0x01 | M5: 0xC1 | N5: 0x00 | O5: 0x02 | P5: 0x00 | Q5: 0x14 | R5: 0x3F | S5: 0xC2
B6: 27 | C6: 0x30 | D6: 0x00 | E6: 0x41 | F6: 0x02 | G6: 0x06 | H6: 0x00 | I6: 0x00 | J6: 0x00 | K6: 0x05 | L6: 0x01 | M6: 0xC1 | N6: 0x00 | O6: 0x0C | P6: 0x00 | Q6: 0x13 | R6: 0x53 | S6: 0x68 | T6: 0x65 | U6: 0x72 | V6: 0x70 | W6: 0x61 | X6: 0x00 | Y6: 0xxx | Z6: 0xxx | AA6: 0xxx | AB6: 0xxx | AC6: 0xxx
B7: 17 | C7: 0x24 | D7: 0x00 | E7: 0x41 | F7: 0x02 | G7: 0x06 | H7: 0x00 | I7: 0x00 | J7: 0x00 | K7: 0x05 | L7: 0x02 | M7: 0x01 | N7: 0x00 | O7: 0x02 | P7: 0x00 | Q7: 0x1D | R7: CRC1 | S7: CRC2

Sheet DATI LOGICI
A1: NOME | B1: INDIRIZZO H (hex) | C1: INDIRIZZO L (hex) | D1: TIPO | E1: FORMATO | F1: MINIMO | G1: MASSIMO | H1: UNITA' DI MISURA | I1: R/W | N1: Ubicazione in App | O1: Nome in App | P1: Aspetto in App | Q1: Effetti in App
A2: DATI STANDARD | J2: SHERPA SLIM | K2: OPTIMUS | L2: GRADINO | M2: EDEN | R2: PACCHIO
A3: Firmware macchina | B3: 0 | C3: 0 | D3: uint16_t | E3: 255.255 | F3: 0 | G3: 255.255 | I3: R | N3: Intestazione Diagnostica 1 | O3: Versione Firmware globale | P3: Sottotitolo Riga elenco | Q3: Nessuno | R3: Dashboard
A4: Firmware scheda | B4: 0 | C4: 1 | D4: uint16_t | E4: 255.255 | F4: 0 | G4: 255.255 | I4: R | N4: Diagnostica | O4: Firmware "scheda" | P4: Riga elenco | Q4: Nessuno | R4: Dashboard
A5: Modello | B5: 0 | C5: 2 | D5: String[20] | I5: R | N5: Intestazione Diagnostica | O5: "Modello" | P5: Titolo Riga elenco | Q5: Nessuno | R5: Dashboard
A6: Matricola | B6: 0 | C6: 3 | D6: uint32_t | F6: 0 | G6: 4294967296 | I6: RW | N6: Intestazione Diagnostica 1 | O6: "Matricola" Numero di serie | P6: Titolo Riga elenco | Q6: Nessuno | R6: Dashboard
A7: Tipo scheda | B7: 0 | C7: 4 | D7: enum dipendente dalle macchine | I7: N | L7: Non Usato
A8: Stato | B8: 0 | C8: 5 | D8: 3*uint32_t | I8: R | J8: dword 0 : numero di riavvii dword 1: stato della macchina all'ultimo riavvio dword 2: tensione di bus all'ultimo riavvio | K8: Cosa si intende? | L8: 0 (UNDEFINED) 1 (NOT_CALIBRATED?) 2 (OPENING_CALIBRATION) 3 (CLOSING_CALIBRATION) 4 (NOT_REPORTED?) 5 (RESETTING) 6 (END_CLOSING) 7 (IN_CLOSING) 8 (END_OPENING) 9 (IN_OPENING)
A9: Allarmi | B9: 0 | C9: 6 | D9: due word uint16_t bitmapped | I9: R | J9: word 0: allarmi: bit 0: fusibile aperto bit 1: sovracorrente bit 2: batteria scarica bit 3: errore motore (aperto) bit 4: errore encoder bit 5: errore CAN bit 6: temperatura scheda elevata bit 7: temperatura ponte elevata bit 8: errore freno bit 9: errore salvataggio posizione word 1: warnings: bit 0: batteria non originale bit 1: batteria bassa bit 2: batteria a fine vita bit 3: blocco motore bit 4: mancanza BLE bit 5: mancanza SM bus bit 6: sensore tensionamento bit 7: errore salvataggio posizione | K9: word 0: allarmi: bit 0: fusibile aperto bit 1: sovracorrente relè bit 2-6: sovracorrente EVx (5 bit) bit 7: batteria scarica bit 8: errore motore (aperto) bit 9-13: EVx aperta (5 bit) bit 14: temperatura uC elevata bit 15: temperatura ponte elevata word 1: warnings: bit 0: batteria veicolo bassa bit 1: mancanza BLE (se impostato presente) bit 2: errore CAN SOLO 2 WORD NON VA BENE | L9: word 0: allarmi: bit 0: fusibile aperto -> DA VERIFICARE! bit 1: sovracorrente relè -> DA VERIFICARE! bit 2-6: sovracorrente EVx (5 bit) -> DA VERIFICARE! bit 7: batteria scarica -> DA VERIFICARE! bit 8: errore motore (aperto) -> DA VERIFICARE! bit 9-13: EVx aperta (5 bit) -> DA VERIFICARE! bit 14: temperatura uC elevata -> DA VERIFICARE! bit 15: temperatura ponte elevata -> DA VERIFICARE! word 1: warnings: bit 0: gradino non completamente aperto bit 1: gradino non completamente chiuso bit 2: batteria veicolo bassa -> DA VERIFICARE! bit 3: mancanza BLE (se impostato presente) -> DA VERIFICARE! bit 4: errore CAN -> DA VERIFICARE! SOLO 2 WORD NON VA BENE | M9: ERRORI Sovratensione Batteria bassa Fusibile aperto Guasto motore Extracorrente motore Elettrovalvola n aperta Bobina EV n non commutata Errore comunicazione CAN n Errore comunicazione BLE Extratemperatura ponte Extratemperatura CPU Intervento costa sensibile AVVISI Urto | N9: Tile Allarmi | O9: Allarmi verificare nome per nome | P9: Sottotitolo in Tile Codice errore | Q9: Cambio colore Tile Apparizione simbolo triangolo Tile | R9: Tile Allarmi
A10: Comandi | B10: 0 | C10: 7 | D10: uint16_t | I10: N | L10: Non Usato | M10: COS'È?
A11: Temperatura scheda | B11: 0 | C11: 8 | D11: uint16_t | I11: R | K11: Temperatura uC se c'è nel Qorvo. | L11: Non Usato
A12: Secondi lavoro motore parziale | B12: 0 | C12: 9 | D12: uint32_t | I12: RW | K12: Motore o Relè a seconda che sia Optimus o Gradino. | L12: Motore | M12: QUESTA ROBA SECONDO ME NON VA NELLE UNIVERSALI | R12: Diagnostica
A13: Secondi lavoro motore totale | B13: 0 | C13: A | D13: uint32_t | I13: RW | K13: Motore o Relè a seconda che sia Optimus o Gradino. | L13: Motore | R13: Diagnostica
A14: Cicli complessivi parziale | B14: 0 | C14: B | D14: uint32_t | I14: RW | K14: Sgancio piano da tutto chiuso (o riaggancio). | L14: Non Usato | R14: Diagnostica
A15: Cicli complessivi totale | B15: 0 | C15: C | D15: uint32_t | I15: RW | K15: Sgancio piano da tutto chiuso (o riaggancio). | L15: Non Usato | R15: Diagnostica
A16: Cicli completi eseguiti parziale | B16: 0 | C16: D | D16: uint32_t | I16: RW | K16: Sgancio, apro tutto, inclino, raddrizzo, chiudo. | L16: Non Usato | R16: Diagnostica
A17: Cicli completi eseguiti totale | B17: 0 | C17: E | D17: uint32_t | I17: RW | K17: Sgancio, apro tutto, inclino, raddrizzo, chiudo. | L17: Non Usato | R17: Diagnostica
A18: Livello batteria | B18: 0 | C18: F | D18: uint16_t | I18: R | K18: Batteria del veicolo. | L18: Non Usato | R18: Diagnostica
A19: Salute batteria | B19: 0 | C19: 10 | D19: uint16_t | I19: R | L19: Non Usato | R19: Diagnostica
A20: Cicli batteria | B20: 0 | C20: 11 | D20: uint16_t | I20: R | L20: Non Usato | R20: Diagnostica
A21: Temperatura batteria | B21: 0 | C21: 12 | D21: int16_t | I21: R | J21: E' in decimi di grado, va divisa per 10 | L21: Non Usato | R21: Diagnostica
A22: BatteryFirmware | B22: 0 | C22: 13 | D22: uint32_t | I22: R | J22: non attivo | L22: Non Usato
A23: BatterySerial | B23: 0 | C23: 14 | D23: uint32_t | I23: R | L23: Non Usato | R23: Diagnostica
A24: Stato ingressi fisici | B24: 0 | C24: 15 | D24: uint32_t | I24: R | J24: bit 0: PIN IN sensore di tensionamento bit 1: stato tasto "Keyboard" scarico/giù bit 2: stato tasto "Keyboard" carico/su bit 3: bit 4: bit 5: stato tasto "Remote Control" scarico/giù bit 6: stato tasto "Remote Control" carico/su bit 7: stato feedback "freno motore" (ANALOG IN) | L24: bit 0: PIN IN sensore di tensionamento bit 1: stato tasto "Keyboard" scarico/giù bit 2: stato tasto "Keyboard" carico/su bit 3: bit 4: bit 5: stato tasto "Remote Control" scarico/giù bit 6: stato tasto "Remote Control" carico/su bit 7: stato feedback "freno motore" (ANALOG IN) | M24: QUESTA ROBA INVECE VA BENE QUI
A25: Stato uscite fisiche | B25: 0 | C25: 16 | D25: uint32_t | I25: R | J25: bit 0: PIN OUT freno motore bit 1: stato motore in movimento se 1, motore fermo se 0 bit 2: stato direzione motore carico/su se 1, direzione motore scarico/giù se 0 bit 3: PIN OUT LED rosso "allarme" bit 4: PIN OUT LED verde "motore in movimento" bit 5: PIN OUT LED tasto ON/OFF "macchina programmata" bit 6: stato buzzer acceso se 1, spento se 0 | L25: bit 0: PIN OUT freno motore bit 1: stato motore in movimento se 1, motore fermo se 0 bit 2: stato direzione motore carico/su se 1, direzione motore scarico/giù se 0 bit 3: PIN OUT LED rosso "allarme" bit 4: PIN OUT LED verde "motore in movimento" bit 5: PIN OUT LED tasto ON/OFF "macchina programmata" bit 6: stato buzzer acceso se 1, spento se 0
A26: Firmware Bootloader | B26: 0 | C26: 17 | D26: uint16_t | E26: 255.255 | F26: 0 | G26: 255.255 | I26: R

Sheet DATI LOGICI SHERPA SLIM
A1: INDIRIZZI SCHEDE A CUI SI APPLICA QUESTO DIZIONARIO
A2: 0x00010041
A3: SHERPA SLIM | B3: INDIRIZZO H (hex) | C3: INDIRIZZO L (hex) | D3: TIPO | E3: FORMATO | F3: MINIMO | G3: MASSIMO | H3: UNITA' DI MISURA | I3: R/W | J3: Significato | K3: Ubicazione in App | L3: Nome in App | M3: Aspetto in App | N3: Effetti in App
A4: DATI SHERPA SLIM
A5: Stato keyboard | B5: 80 | C5: 0 | D5: uint8_t | I5: N
A6: DATI AZIONAMENTO
A7: Motor Running | B7: 80 | C7: 1 | D7: bool | F7: 0 | G7: 1 | I7: R | J7: 0 = motore fermo, 1 = motore in movimento
A8: Motor Type | B8: 80 | C8: 2 | D8: enum | F8: 0 | G8: 4 | I8: R | J8: 0 = Not initialized 1 = DC BRUSHLESS 2 = DC 3 = AC INDUCTION 4 = AC BRUSHLESS | O8: Magari mettere tra i motor Type anche l'ON/OFF tipo relè come questo.
A9: Motor Position Reference | B9: 80 | C9: 3 | D9: int16_t | I9: R
A10: Motor Position | B10: =B7 -> 80 | C10: =C9+1 -> 4 | D10: int16_t | I10: R | K10: Diagnostica/Motore | L10: Posizione | M10: Elenco | N10: Nessuno
A11: Position PID enabled | B11: =B8 -> 80 | C11: =C10+1 -> 5 | D11: bool | I11: R
A12: Position PID KP | B12: =B9 -> 80 | C12: =C11+1 -> 6 | D12: int16_t | I12: RW | K12: Diagnostica/Motore | L12: KP PID posizione | M12: Elenco | N12: Nessuno
A13: Position PID KI | B13: =B10 -> 80 | C13: =C12+1 -> 7 | D13: int32_t | I13: RW | K13: Diagnostica/Motore | L13: KI PID posizione | M13: Elenco | N13: Nessuno
A14: Motor Speed Reference | B14: =B11 -> 80 | C14: =C13+1 -> 8 | D14: int16_t | I14: R | O14: Solo per il gradino, l'Optimus è un relè quindi ON/OFF.
A15: Motor Speed | B15: =B12 -> 80 | C15: =C14+1 -> 9 | D15: int16_t | I15: R | K15: Diagnostica/Motore | L15: Velocità | M15: Elenco | N15: Nessuno
A16: Speed PID enabled | B16: =B13 -> 80 | C16: A | D16: bool | I16: R
A17: Speed PID KP | B17: =B14 -> 80 | C17: B | D17: int16_t | I17: RW | K17: Diagnostica/Motore | L17: KP PID velocità | M17: Elenco | N17: Nessuno
A18: Speed PID KI | B18: =B15 -> 80 | C18: C | D18: int32_t | I18: RW | K18: Diagnostica/Motore | L18: KI PID velocità | M18: Elenco | N18: Nessuno
A19: I reference | B19: 80 | C19: D | D19: int16_t | I19: R
A20: Motor I | B20: 80 | C20: E | D20: int16_t | I20: R | K20: Diagnostica/Motore | L20: Corrente | M20: Elenco | N20: Nessuno
A21: enabled I PID | B21: 80 | C21: F | D21: bool | I21: R
A22: Kp I PID | B22: 80 | C22: 10 | D22: int16_t | I22: RW | K22: Diagnostica/Motore | L22: KP PID velocità | M22: Elenco | N22: Nessuno
A23: Ki I PID | B23: 80 | C23: =C22+1 -> 11 | D23: int32_t | I23: RW | K23: Diagnostica/Motore | L23: KI PID velocità | M23: Elenco | N23: Nessuno
A24: Voltage reference applied to the motor | B24: 80 | C24: =C23+1 -> 12 | D24: int16_t | I24: R
A25: Vbus measured | B25: 80 | C25: =C24+1 -> 13 | D25: uint16_t | I25: R
A26: Motor faults | B26: 80 | C26: =C25+1 -> 14 | D26: uint32_t | I26: RW | K26: Diagnostica/Motore | L26: Guasti motore | M26: Elenco | N26: Nessuno | O26: Quali sono i faults?
A27: Motor warnings | B27: 80 | C27: =C26+1 -> 15 | D27: uint32_t | I27: RW | K27: Diagnostica/Motore | L27: Avvisi motore | M27: Elenco | N27: Nessuno | O27: Quali sono i warning?
A28: Number of pulses when breaking in position loop control | B28: 80 | C28: =C27+1 -> 16 | D28: uint16_t | I28: RW
A29: Time for out of control thermal fault (in ms) | B29: 80 | C29: =C28+1 -> 17 | D29: int32_t | I29: RW | O29: Ci sta che il controllo termico valga anche per il relè anche se sarà molto improbabile.
A30: DATI SHERPA SLIM
A31: Working mode | B31: 80 | C31: 2E | D31: uint32_t | I31: RW | J31: 0 = funzionameto normale 1 = funzionameto automatico di test 2 = funzionameto manuale di test | K31: Diagnostica
A32: Stato posizione/in mezzo | B32: 80 | C32: 2F | D32: uint8_t | I32: R | J32: 0 = in mezzo, 1 = in posizione | K32: Diagnostica
A33: Stato movimento motore | B33: 80 | C33: 30 | D33: uint8_t | I33: R | K33: Diagnostica
A34: Estremo posizione | B34: 80 | C34: 31 | D34: uint16_t | I34: R
A35: Posizione punto 1 | B35: 80 | C35: 32 | D35: int32_t | I35: R
A36: Posizione punto 2 | B36: 80 | C36: 33 | D36: int32_t | I36: R
A37: Posizione punto 3 | B37: 80 | C37: 34 | D37: int32_t | I37: R
A38: Posizione punto 4 | B38: 80 | C38: 35 | D38: int32_t | I38: R
A39: Posizione punto 5 | B39: 80 | C39: 36 | D39: int32_t | I39: R
A40: Posizione punto 6 | B40: 80 | C40: 37 | D40: int32_t | I40: R
...

Sheet DATI LOGICI EDEN
A1: INDIRIZZI SCHEDE A CUI SI APPLICA QUESTO DIZIONARIO
A2: 0x00030141
A3: EDEN | B3: INDIRIZZO H+L (hex) | D3: TIPO | E3: FORMATO | F3: MINIMO | G3: MASSIMO | H3: UNITA' DI MISURA | I3: R/W | J3: Uso | K3: Significato | L3: Ubicazione in App | M3: Nome in App | N3: Aspetto in App | O3: Effetti in App
A4: DATI STANDARD
A5: =IF('DATI LOGICI'!A3<>"",'DATI LOGICI'!A3,"") -> Firmware macchina | B5: =IF('DATI LOGICI'!B3<>"",'DATI LOGICI'!B3,"") -> 0 | C5: =IF('DATI LOGICI'!C3<>"",'DATI LOGICI'!C3,"") -> 0 | D5: =IF('DATI LOGICI'!D3<>"",'DATI LOGICI'!D3,"") -> uint16_t | E5: =IF('DATI LOGICI'!E3<>"",'DATI LOGICI'!E3,"") -> 255.255 | F5: =IF('DATI LOGICI'!F3<>"",'DATI LOGICI'!F3,"") -> 0 | G5: =IF('DATI LOGICI'!G3<>"",'DATI LOGICI'!G3,"") -> 255.255 | H5: =IF('DATI LOGICI'!H3<>"",'DATI LOGICI'!H3,"") | I5: =IF('DATI LOGICI'!I3<>"",'DATI LOGICI'!I3,"") -> R
A6: =IF('DATI LOGICI'!A4<>"",'DATI LOGICI'!A4,"") -> Firmware scheda | B6: =IF('DATI LOGICI'!B4<>"",'DATI LOGICI'!B4,"") -> 0 | C6: =IF('DATI LOGICI'!C4<>"",'DATI LOGICI'!C4,"") -> 1 | D6: =IF('DATI LOGICI'!D4<>"",'DATI LOGICI'!D4,"") -> uint16_t | E6: =IF('DATI LOGICI'!E4<>"",'DATI LOGICI'!E4,"") -> 255.255 | F6: =IF('DATI LOGICI'!F4<>"",'DATI LOGICI'!F4,"") -> 0 | G6: =IF('DATI LOGICI'!G4<>"",'DATI LOGICI'!G4,"") -> 255.255 | H6: =IF('DATI LOGICI'!H4<>"",'DATI LOGICI'!H4,"") | I6: =IF('DATI LOGICI'!I4<>"",'DATI LOGICI'!I4,"") -> R
A7: =IF('DATI LOGICI'!A5<>"",'DATI LOGICI'!A5,"") -> Modello | B7: =IF('DATI LOGICI'!B5<>"",'DATI LOGICI'!B5,"") -> 0 | C7: =IF('DATI LOGICI'!C5<>"",'DATI LOGICI'!C5,"") -> 2 | D7: =IF('DATI LOGICI'!D5<>"",'DATI LOGICI'!D5,"") -> String[20] | E7: =IF('DATI LOGICI'!E5<>"",'DATI LOGICI'!E5,"") | F7: =IF('DATI LOGICI'!F5<>"",'DATI LOGICI'!F5,"") | G7: =IF('DATI LOGICI'!G5<>"",'DATI LOGICI'!G5,"") | H7: =IF('DATI LOGICI'!H5<>"",'DATI LOGICI'!H5,"") | I7: =IF('DATI LOGICI'!I5<>"",'DATI LOGICI'!I5,"") -> R | K7: Valore fisso:"Eden"
A8: =IF('DATI LOGICI'!A6<>"",'DATI LOGICI'!A6,"") -> Matricola | B8: =IF('DATI LOGICI'!B6<>"",'DATI LOGICI'!B6,"") -> 0 | C8: =IF('DATI LOGICI'!C6<>"",'DATI LOGICI'!C6,"") -> 3 | D8: =IF('DATI LOGICI'!D6<>"",'DATI LOGICI'!D6,"") -> uint32_t | E8: =IF('DATI LOGICI'!E6<>"",'DATI LOGICI'!E6,"") | F8: =IF('DATI LOGICI'!F6<>"",'DATI LOGICI'!F6,"") -> 0 | G8: =IF('DATI LOGICI'!G6<>"",'DATI LOGICI'!G6,"") -> 4294967296 | H8: =IF('DATI LOGICI'!H6<>"",'DATI LOGICI'!H6,"") | I8: =IF('DATI LOGICI'!I6<>"",'DATI LOGICI'!I6,"") -> RW
A9: =IF('DATI LOGICI'!A7<>"",'DATI LOGICI'!A7,"") -> Tipo scheda | B9: =IF('DATI LOGICI'!B7<>"",'DATI LOGICI'!B7,"") -> 0 | C9: =IF('DATI LOGICI'!C7<>"",'DATI LOGICI'!C7,"") -> 4 | D9: =IF('DATI LOGICI'!D7<>"",'DATI LOGICI'!D7,"") -> enum dipendente dalle macchine | E9: =IF('DATI LOGICI'!E7<>"",'DATI LOGICI'!E7,"") | F9: =IF('DATI LOGICI'!F7<>"",'DATI LOGICI'!F7,"") | G9: =IF('DATI LOGICI'!G7<>"",'DATI LOGICI'!G7,"") | H9: =IF('DATI LOGICI'!H7<>"",'DATI LOGICI'!H7,"") | I9: R | K9: Valore fisso: 5
A10: =IF('DATI LOGICI'!A8<>"",'DATI LOGICI'!A8,"") -> Stato | B10: =IF('DATI LOGICI'!B8<>"",'DATI LOGICI'!B8,"") -> 0 | C10: =IF('DATI LOGICI'!C8<>"",'DATI LOGICI'!C8,"") -> 5 | D10: =IF('DATI LOGICI'!D8<>"",'DATI LOGICI'!D8,"") -> 3*uint32_t | E10: =IF('DATI LOGICI'!E8<>"",'DATI LOGICI'!E8,"") | F10: =IF('DATI LOGICI'!F8<>"",'DATI LOGICI'!F8,"") | G10: =IF('DATI LOGICI'!G8<>"",'DATI LOGICI'!G8,"") | H10: =IF('DATI LOGICI'!H8<>"",'DATI LOGICI'!H8,"") | I10: =IF('DATI LOGICI'!I8<>"",'DATI LOGICI'!I8,"") -> R
A11: =IF('DATI LOGICI'!A9<>"",'DATI LOGICI'!A9,"") -> Allarmi | B11: =IF('DATI LOGICI'!B9<>"",'DATI LOGICI'!B9,"") -> 0 | C11: =IF('DATI LOGICI'!C9<>"",'DATI LOGICI'!C9,"") -> 6 | D11: =IF('DATI LOGICI'!D9<>"",'DATI LOGICI'!D9,"") -> due word uint16_t bitmapped | E11: =IF('DATI LOGICI'!E9<>"",'DATI LOGICI'!E9,"") | F11: =IF('DATI LOGICI'!F9<>"",'DATI LOGICI'!F9,"") | G11: =IF('DATI LOGICI'!G9<>"",'DATI LOGICI'!G9,"") | H11: =IF('DATI LOGICI'!H9<>"",'DATI LOGICI'!H9,"") | I11: =IF('DATI LOGICI'!I9<>"",'DATI LOGICI'!I9,"") -> R | J11: Log GD | K11: WORD 1: allarmi: bit 0: sovracorrente pompa bit 1: circuito aperto pompa bit 2: sovracorrente EV 1 bit 3: circuito aperto EV 1 bit 4: sovracorrente EV 2 bit 5: circuito aperto EV 2 bit 6: sovracorrente EV 3 bit 7: circuito aperto EV 3 bit 8: sovracorrente EV 4 bit 9: circuito aperto EV 4 bit 10: sovracorrente EV 5 bit 11: circuito aperto EV 5 bit 12: sovracorrente EV 6 bit 13: circuito aperto EV 6 bit 14: sovracorrente EV 7 bit 15: circuito aperto EV 7 WORD 2: allarmi: bit 0: sovracorrente EV 8 bit 1: circuito aperto EV 8 bit2: low battery bit3: costa sensibile bit4: Errore interno routine software bit5: errore hardware EEPROM esterna WORD 3: allarmi: WORD 4: allarmi: WORD 5: warnings: WORD 6: WORD 7: WORD 8:
A12: =IF('DATI LOGICI'!A10<>"",'DATI LOGICI'!A10,"") -> Comandi | B12: =IF('DATI LOGICI'!B10<>"",'DATI LOGICI'!B10,"") -> 0 | C12: =IF('DATI LOGICI'!C10<>"",'DATI LOGICI'!C10,"") -> 7 | D12: =IF('DATI LOGICI'!D10<>"",'DATI LOGICI'!D10,"") -> uint16_t | E12: =IF('DATI LOGICI'!E10<>"",'DATI LOGICI'!E10,"") | F12: =IF('DATI LOGICI'!F10<>"",'DATI LOGICI'!F10,"") | G12: =IF('DATI LOGICI'!G10<>"",'DATI LOGICI'!G10,"") | H12: =IF('DATI LOGICI'!H10<>"",'DATI LOGICI'!H10,"") | I12: =IF('DATI LOGICI'!I10<>"",'DATI LOGICI'!I10,"") -> N
A13: =IF('DATI LOGICI'!A11<>"",'DATI LOGICI'!A11,"") -> Temperatura scheda | B13: =IF('DATI LOGICI'!B11<>"",'DATI LOGICI'!B11,"") -> 0 | C13: =IF('DATI LOGICI'!C11<>"",'DATI LOGICI'!C11,"") -> 8 | D13: float | E13: =IF('DATI LOGICI'!E11<>"",'DATI LOGICI'!E11,"") | F13: =IF('DATI LOGICI'!F11<>"",'DATI LOGICI'!F11,"") | G13: =IF('DATI LOGICI'!G11<>"",'DATI LOGICI'!G11,"") | H13: =IF('DATI LOGICI'!H11<>"",'DATI LOGICI'!H11,"") | I13: =IF('DATI LOGICI'!I11<>"",'DATI LOGICI'!I11,"") -> R | K13: temperatura interna al micro in gradi
A14: =IF('DATI LOGICI'!A12<>"",'DATI LOGICI'!A12,"") -> Secondi lavoro motore parziale | B14: =IF('DATI LOGICI'!B12<>"",'DATI LOGICI'!B12,"") -> 0 | C14: =IF('DATI LOGICI'!C12<>"",'DATI LOGICI'!C12,"") -> 9 | D14: =IF('DATI LOGICI'!D12<>"",'DATI LOGICI'!D12,"") -> uint32_t | E14: =IF('DATI LOGICI'!E12<>"",'DATI LOGICI'!E12,"") | F14: =IF('DATI LOGICI'!F12<>"",'DATI LOGICI'!F12,"") | G14: =IF('DATI LOGICI'!G12<>"",'DATI LOGICI'!G12,"") | H14: =IF('DATI LOGICI'!H12<>"",'DATI LOGICI'!H12,"") | I14: =IF('DATI LOGICI'!I12<>"",'DATI LOGICI'!I12,"") -> RW | K14: secondi di lavoro parziale della macchina
A15: =IF('DATI LOGICI'!A13<>"",'DATI LOGICI'!A13,"") -> Secondi lavoro motore totale | B15: =IF('DATI LOGICI'!B13<>"",'DATI LOGICI'!B13,"") -> 0 | C15: =IF('DATI LOGICI'!C13<>"",'DATI LOGICI'!C13,"") -> A | D15: =IF('DATI LOGICI'!D13<>"",'DATI LOGICI'!D13,"") -> uint32_t | E15: =IF('DATI LOGICI'!E13<>"",'DATI LOGICI'!E13,"") | F15: =IF('DATI LOGICI'!F13<>"",'DATI LOGICI'!F13,"") | G15: =IF('DATI LOGICI'!G13<>"",'DATI LOGICI'!G13,"") | H15: =IF('DATI LOGICI'!H13<>"",'DATI LOGICI'!H13,"") | I15: =IF('DATI LOGICI'!I13<>"",'DATI LOGICI'!I13,"") -> RW | K15: secondi di lavoro totale della macchina
A16: =IF('DATI LOGICI'!A14<>"",'DATI LOGICI'!A14,"") -> Cicli complessivi parziale | B16: =IF('DATI LOGICI'!B14<>"",'DATI LOGICI'!B14,"") -> 0 | C16: =IF('DATI LOGICI'!C14<>"",'DATI LOGICI'!C14,"") -> B | D16: =IF('DATI LOGICI'!D14<>"",'DATI LOGICI'!D14,"") -> uint32_t | E16: =IF('DATI LOGICI'!E14<>"",'DATI LOGICI'!E14,"") | F16: =IF('DATI LOGICI'!F14<>"",'DATI LOGICI'!F14,"") | G16: =IF('DATI LOGICI'!G14<>"",'DATI LOGICI'!G14,"") | H16: =IF('DATI LOGICI'!H14<>"",'DATI LOGICI'!H14,"") | I16: =IF('DATI LOGICI'!I14<>"",'DATI LOGICI'!I14,"") -> RW | K16: numero cicli di lavoro non completi parziale
A17: =IF('DATI LOGICI'!A15<>"",'DATI LOGICI'!A15,"") -> Cicli complessivi totale | B17: =IF('DATI LOGICI'!B15<>"",'DATI LOGICI'!B15,"") -> 0 | C17: =IF('DATI LOGICI'!C15<>"",'DATI LOGICI'!C15,"") -> C | D17: =IF('DATI LOGICI'!D15<>"",'DATI LOGICI'!D15,"") -> uint32_t | E17: =IF('DATI LOGICI'!E15<>"",'DATI LOGICI'!E15,"") | F17: =IF('DATI LOGICI'!F15<>"",'DATI LOGICI'!F15,"") | G17: =IF('DATI LOGICI'!G15<>"",'DATI LOGICI'!G15,"") | H17: =IF('DATI LOGICI'!H15<>"",'DATI LOGICI'!H15,"") | I17: =IF('DATI LOGICI'!I15<>"",'DATI LOGICI'!I15,"") -> RW | K17: numero cicli di lavoro non completi totale
A18: =IF('DATI LOGICI'!A16<>"",'DATI LOGICI'!A16,"") -> Cicli completi eseguiti parziale | B18: =IF('DATI LOGICI'!B16<>"",'DATI LOGICI'!B16,"") -> 0 | C18: =IF('DATI LOGICI'!C16<>"",'DATI LOGICI'!C16,"") -> D | D18: =IF('DATI LOGICI'!D16<>"",'DATI LOGICI'!D16,"") -> uint32_t | E18: =IF('DATI LOGICI'!E16<>"",'DATI LOGICI'!E16,"") | F18: =IF('DATI LOGICI'!F16<>"",'DATI LOGICI'!F16,"") | G18: =IF('DATI LOGICI'!G16<>"",'DATI LOGICI'!G16,"") | H18: =IF('DATI LOGICI'!H16<>"",'DATI LOGICI'!H16,"") | I18: =IF('DATI LOGICI'!I16<>"",'DATI LOGICI'!I16,"") -> RW | K18: numero cicli di lavoro completi parziale
A19: =IF('DATI LOGICI'!A17<>"",'DATI LOGICI'!A17,"") -> Cicli completi eseguiti totale | B19: =IF('DATI LOGICI'!B17<>"",'DATI LOGICI'!B17,"") -> 0 | C19: =IF('DATI LOGICI'!C17<>"",'DATI LOGICI'!C17,"") -> E | D19: =IF('DATI LOGICI'!D17<>"",'DATI LOGICI'!D17,"") -> uint32_t | E19: =IF('DATI LOGICI'!E17<>"",'DATI LOGICI'!E17,"") | F19: =IF('DATI LOGICI'!F17<>"",'DATI LOGICI'!F17,"") | G19: =IF('DATI LOGICI'!G17<>"",'DATI LOGICI'!G17,"") | H19: =IF('DATI LOGICI'!H17<>"",'DATI LOGICI'!H17,"") | I19: =IF('DATI LOGICI'!I17<>"",'DATI LOGICI'!I17,"") -> RW | K19: numero cicli di lavoro completi totale
A20: =IF('DATI LOGICI'!A18<>"",'DATI LOGICI'!A18,"") -> Livello batteria | B20: =IF('DATI LOGICI'!B18<>"",'DATI LOGICI'!B18,"") -> 0 | C20: =IF('DATI LOGICI'!C18<>"",'DATI LOGICI'!C18,"") -> F | D20: =IF('DATI LOGICI'!D18<>"",'DATI LOGICI'!D18,"") -> uint16_t | E20: =IF('DATI LOGICI'!E18<>"",'DATI LOGICI'!E18,"") | F20: 0 | G20: 100 | H20: % | I20: =IF('DATI LOGICI'!I18<>"",'DATI LOGICI'!I18,"") -> R | K20: Derivato dalla tensione misurata, in percentaule
A21: =IF('DATI LOGICI'!A19<>"",'DATI LOGICI'!A19,"") -> Salute batteria | B21: =IF('DATI LOGICI'!B19<>"",'DATI LOGICI'!B19,"") -> 0 | C21: =IF('DATI LOGICI'!C19<>"",'DATI LOGICI'!C19,"") -> 10 | D21: =IF('DATI LOGICI'!D19<>"",'DATI LOGICI'!D19,"") -> uint16_t | E21: =IF('DATI LOGICI'!E19<>"",'DATI LOGICI'!E19,"") | F21: =IF('DATI LOGICI'!F19<>"",'DATI LOGICI'!F19,"") | G21: =IF('DATI LOGICI'!G19<>"",'DATI LOGICI'!G19,"") | H21: =IF('DATI LOGICI'!H19<>"",'DATI LOGICI'!H19,"") | I21: =IF('DATI LOGICI'!I19<>"",'DATI LOGICI'!I19,"") -> R
A22: =IF('DATI LOGICI'!A20<>"",'DATI LOGICI'!A20,"") -> Cicli batteria | B22: =IF('DATI LOGICI'!B20<>"",'DATI LOGICI'!B20,"") -> 0 | C22: =IF('DATI LOGICI'!C20<>"",'DATI LOGICI'!C20,"") -> 11 | D22: =IF('DATI LOGICI'!D20<>"",'DATI LOGICI'!D20,"") -> uint16_t | E22: =IF('DATI LOGICI'!E20<>"",'DATI LOGICI'!E20,"") | F22: =IF('DATI LOGICI'!F20<>"",'DATI LOGICI'!F20,"") | G22: =IF('DATI LOGICI'!G20<>"",'DATI LOGICI'!G20,"") | H22: =IF('DATI LOGICI'!H20<>"",'DATI LOGICI'!H20,"") | I22: =IF('DATI LOGICI'!I20<>"",'DATI LOGICI'!I20,"") -> R
A23: =IF('DATI LOGICI'!A21<>"",'DATI LOGICI'!A21,"") -> Temperatura batteria | B23: =IF('DATI LOGICI'!B21<>"",'DATI LOGICI'!B21,"") -> 0 | C23: =IF('DATI LOGICI'!C21<>"",'DATI LOGICI'!C21,"") -> 12 | D23: =IF('DATI LOGICI'!D21<>"",'DATI LOGICI'!D21,"") -> int16_t | E23: =IF('DATI LOGICI'!E21<>"",'DATI LOGICI'!E21,"") | F23: =IF('DATI LOGICI'!F21<>"",'DATI LOGICI'!F21,"") | G23: =IF('DATI LOGICI'!G21<>"",'DATI LOGICI'!G21,"") | H23: =IF('DATI LOGICI'!H21<>"",'DATI LOGICI'!H21,"") | I23: =IF('DATI LOGICI'!I21<>"",'DATI LOGICI'!I21,"") -> R
A24: =IF('DATI LOGICI'!A22<>"",'DATI LOGICI'!A22,"") -> BatteryFirmware | B24: =IF('DATI LOGICI'!B22<>"",'DATI LOGICI'!B22,"") -> 0 | C24: =IF('DATI LOGICI'!C22<>"",'DATI LOGICI'!C22,"") -> 13 | D24: =IF('DATI LOGICI'!D22<>"",'DATI LOGICI'!D22,"") -> uint32_t | E24: =IF('DATI LOGICI'!E22<>"",'DATI LOGICI'!E22,"") | F24: =IF('DATI LOGICI'!F22<>"",'DATI LOGICI'!F22,"") | G24: =IF('DATI LOGICI'!G22<>"",'DATI LOGICI'!G22,"") | H24: =IF('DATI LOGICI'!H22<>"",'DATI LOGICI'!H22,"") | I24: =IF('DATI LOGICI'!I22<>"",'DATI LOGICI'!I22,"") -> R
A25: =IF('DATI LOGICI'!A23<>"",'DATI LOGICI'!A23,"") -> BatterySerial | B25: =IF('DATI LOGICI'!B23<>"",'DATI LOGICI'!B23,"") -> 0 | C25: =IF('DATI LOGICI'!C23<>"",'DATI LOGICI'!C23,"") -> 14 | D25: =IF('DATI LOGICI'!D23<>"",'DATI LOGICI'!D23,"") -> uint32_t | E25: =IF('DATI LOGICI'!E23<>"",'DATI LOGICI'!E23,"") | F25: =IF('DATI LOGICI'!F23<>"",'DATI LOGICI'!F23,"") | G25: =IF('DATI LOGICI'!G23<>"",'DATI LOGICI'!G23,"") | H25: =IF('DATI LOGICI'!H23<>"",'DATI LOGICI'!H23,"") | I25: =IF('DATI LOGICI'!I23<>"",'DATI LOGICI'!I23,"") -> R
A26: =IF('DATI LOGICI'!A24<>"",'DATI LOGICI'!A24,"") -> Stato ingressi fisici | B26: =IF('DATI LOGICI'!B24<>"",'DATI LOGICI'!B24,"") -> 0 | C26: =IF('DATI LOGICI'!C24<>"",'DATI LOGICI'!C24,"") -> 15 | D26: =IF('DATI LOGICI'!D24<>"",'DATI LOGICI'!D24,"") -> uint32_t | E26: =IF('DATI LOGICI'!E24<>"",'DATI LOGICI'!E24,"") | F26: =IF('DATI LOGICI'!F24<>"",'DATI LOGICI'!F24,"") | G26: =IF('DATI LOGICI'!G24<>"",'DATI LOGICI'!G24,"") | H26: =IF('DATI LOGICI'!H24<>"",'DATI LOGICI'!H24,"") | I26: =IF('DATI LOGICI'!I24<>"",'DATI LOGICI'!I24,"") -> R | K26: bit 0: FC Estratto bit 1: FC Chiuso bit 2: Comando UP bit 3: Comando Down bit 4: Costa sensibile bit 5: Comando tastiera testa su bit 6: Comando tastiera piedi su bit 7: Comando tastiera vai orizzontale bit 8: Comando tastiera molleggio bit 9: Comando tastiera tutto su bit 10: Comando tastiera tutto giu' bit 11: Comando tastiera stop
A27: =IF('DATI LOGICI'!A25<>"",'DATI LOGICI'!A25,"") -> Stato uscite fisiche | B27: =IF('DATI LOGICI'!B25<>"",'DATI LOGICI'!B25,"") -> 0 | C27: =IF('DATI LOGICI'!C25<>"",'DATI LOGICI'!C25,"") -> 16 | D27: =IF('DATI LOGICI'!D25<>"",'DATI LOGICI'!D25,"") -> uint32_t | E27: =IF('DATI LOGICI'!E25<>"",'DATI LOGICI'!E25,"") | F27: =IF('DATI LOGICI'!F25<>"",'DATI LOGICI'!F25,"") | G27: =IF('DATI LOGICI'!G25<>"",'DATI LOGICI'!G25,"") | H27: =IF('DATI LOGICI'!H25<>"",'DATI LOGICI'!H25,"") | I27: =IF('DATI LOGICI'!I25<>"",'DATI LOGICI'!I25,"") -> R | K27: bit 0: EV1 bit 1: EV2 bit 2: EV3 bit 3: EV4 bit 4: EV5 bit 5: EV6 bit 6: EV7 bit 7: EV8 bit 8: PUMP bit 9: LEDB bit 10: LEDG bit 11: LEDR
A28: =IF('DATI LOGICI'!A26<>"",'DATI LOGICI'!A26,"") -> Firmware Bootloader | B28: =IF('DATI LOGICI'!B26<>"",'DATI LOGICI'!B26,"") -> 0 | C28: =IF('DATI LOGICI'!C26<>"",'DATI LOGICI'!C26,"") -> 17 | D28: =IF('DATI LOGICI'!D26<>"",'DATI LOGICI'!D26,"") -> uint16_t | E28: =IF('DATI LOGICI'!E26<>"",'DATI LOGICI'!E26,"") -> 255.255 | F28: =IF('DATI LOGICI'!F26<>"",'DATI LOGICI'!F26,"") -> 0 | G28: =IF('DATI LOGICI'!G26<>"",'DATI LOGICI'!G26,"") -> 255.255 | H28: =IF('DATI LOGICI'!H26<>"",'DATI LOGICI'!H26,"") | I28: =IF('DATI LOGICI'!I26<>"",'DATI LOGICI'!I26,"") -> R
A30: DATI LOGICI EDEN
A31: Stato keyboard 1 | B31: 80 | C31: =DEC2HEX(0) -> 0 | D31: uint8_t | I31: N | K31: Variabile logica gestita dalla tastiera esterna (non usare con l'app)
A32: SystemOn | B32: 80 | C32: =DEC2HEX(HEX2DEC(C31)+1) -> 1 | D32: bool | F32: 0 | G32: 1 | I32: R | K32: 0 = piano spento, 1 = piano acceso
A33: Angolo inclinazione del piano | B33: 80 | C33: =DEC2HEX(HEX2DEC(C32)+1) -> 2 | D33: float | H33: gradi | I33: R | K33: Angolo di inclinazione del piano: 12.0 è testa su massimo, -12.0 e piedi su massimo, 0.0 è orizzontale
A34: Angolo lato testa | B34: 80 | C34: =DEC2HEX(HEX2DEC(C33)+1) -> 3 | D34: float | H34: gradi | I34: R | K34: Angolo di inclinazione calcolato lato testa (si usa a piano chiuso)
A35: Tastiera SherpaSlim | B35: 80 | C35: =DEC2HEX(HEX2DEC(C34)+1) -> 4 | D35: uint8_t | K35: Immagine tasti SherpaSlim per gestire i 2 blu
A36: Potenzio inclinazione min | B36: 80 | C36: =DEC2HEX(HEX2DEC(C35)+1) -> 5 | D36: uint16_t | F36: 0 | G36: 65535 | H36: bits | I36: R/W | K36: Valore minimo in bits letto dal valore RAW del potenzio in apprendimento
A37: Potenzio inclinazione max | B37: 80 | C37: =DEC2HEX(HEX2DEC(C36)+1) -> 6 | D37: uint16_t | F37: 0 | G37: 65535 | H37: bits | I37: R/W | K37: Valore massimo in bits letto dal valore RAW del potenzio in apprendimento
A38: Potenzio altezza min | B38: 80 | C38: =DEC2HEX(HEX2DEC(C37)+1) -> 7 | D38: uint16_t | F38: 0 | G38: 65535 | H38: bits | I38: R/W | K38: Valore minimo in bits letto dal valore RAW del potenzio in apprendimento
A39: Potenzio altezza max | B39: 80 | C39: =DEC2HEX(HEX2DEC(C38)+1) -> 8 | D39: uint16_t | F39: 0 | G39: 65535 | H39: bits | I39: R/W | K39: Valore massimo in bits letto dal valore RAW del potenzio in apprendimento
A40: Angolo X | B40: 80 | C40: =DEC2HEX(HEX2DEC(C39)+1) -> 9 | D40: float | F40: -180 | G40: 180 | H40: gradi | I40: R
A41: Angolo Y | B41: 80 | C41: =DEC2HEX(HEX2DEC(C40)+1) -> A | D41: float | F41: -180 | G41: 180 | H41: gradi | I41: R
...

Sheet DATI LOGICI TASTIERA PAC
A1: INDIRIZZI SCHEDE A CUI SI APPLICA QUESTO DIZIONARIO
A2: 0x00030101 | B2: 0x000803C1 | C2: 0x000803C2 | D2: 0x000803C3 | E2: 0x00030102 | F2: 0x00030103 | G2: 0x00020101
A3: TASTIERA | B3: INDIRIZZO H+L (hex) | D3: TIPO | E3: FORMATO | F3: MINIMO | G3: MASSIMO | H3: UNITA' DI MISURA | I3: R/W | J3: Uso | K3: Significato | L3: Ubicazione in App | M3: Nome in App | N3: Aspetto in App | O3: Effetti in App
A4: DATI STANDARD
A5: =IF('DATI LOGICI'!A3<>"",'DATI LOGICI'!A3,"") -> Firmware macchina | B5: =IF('DATI LOGICI'!B3<>"",'DATI LOGICI'!B3,"") -> 0 | C5: =IF('DATI LOGICI'!C3<>"",'DATI LOGICI'!C3,"") -> 0 | D5: =IF('DATI LOGICI'!D3<>"",'DATI LOGICI'!D3,"") -> uint16_t | E5: =IF('DATI LOGICI'!E3<>"",'DATI LOGICI'!E3,"") -> 255.255 | F5: =IF('DATI LOGICI'!F3<>"",'DATI LOGICI'!F3,"") -> 0 | G5: =IF('DATI LOGICI'!G3<>"",'DATI LOGICI'!G3,"") -> 255.255 | H5: =IF('DATI LOGICI'!H3<>"",'DATI LOGICI'!H3,"") | I5: =IF('DATI LOGICI'!I3<>"",'DATI LOGICI'!I3,"") -> R
A6: =IF('DATI LOGICI'!A4<>"",'DATI LOGICI'!A4,"") -> Firmware scheda | B6: =IF('DATI LOGICI'!B4<>"",'DATI LOGICI'!B4,"") -> 0 | C6: =IF('DATI LOGICI'!C4<>"",'DATI LOGICI'!C4,"") -> 1 | D6: =IF('DATI LOGICI'!D4<>"",'DATI LOGICI'!D4,"") -> uint16_t | E6: =IF('DATI LOGICI'!E4<>"",'DATI LOGICI'!E4,"") -> 255.255 | F6: =IF('DATI LOGICI'!F4<>"",'DATI LOGICI'!F4,"") -> 0 | G6: =IF('DATI LOGICI'!G4<>"",'DATI LOGICI'!G4,"") -> 255.255 | H6: =IF('DATI LOGICI'!H4<>"",'DATI LOGICI'!H4,"") | I6: =IF('DATI LOGICI'!I4<>"",'DATI LOGICI'!I4,"") -> R
A7: =IF('DATI LOGICI'!A5<>"",'DATI LOGICI'!A5,"") -> Modello | B7: =IF('DATI LOGICI'!B5<>"",'DATI LOGICI'!B5,"") -> 0 | C7: =IF('DATI LOGICI'!C5<>"",'DATI LOGICI'!C5,"") -> 2 | D7: =IF('DATI LOGICI'!D5<>"",'DATI LOGICI'!D5,"") -> String[20] | E7: =IF('DATI LOGICI'!E5<>"",'DATI LOGICI'!E5,"") | F7: =IF('DATI LOGICI'!F5<>"",'DATI LOGICI'!F5,"") | G7: =IF('DATI LOGICI'!G5<>"",'DATI LOGICI'!G5,"") | H7: =IF('DATI LOGICI'!H5<>"",'DATI LOGICI'!H5,"") | I7: =IF('DATI LOGICI'!I5<>"",'DATI LOGICI'!I5,"") -> R
A8: =IF('DATI LOGICI'!A6<>"",'DATI LOGICI'!A6,"") -> Matricola | B8: =IF('DATI LOGICI'!B6<>"",'DATI LOGICI'!B6,"") -> 0 | C8: =IF('DATI LOGICI'!C6<>"",'DATI LOGICI'!C6,"") -> 3 | D8: =IF('DATI LOGICI'!D6<>"",'DATI LOGICI'!D6,"") -> uint32_t | E8: =IF('DATI LOGICI'!E6<>"",'DATI LOGICI'!E6,"") | F8: =IF('DATI LOGICI'!F6<>"",'DATI LOGICI'!F6,"") -> 0 | G8: =IF('DATI LOGICI'!G6<>"",'DATI LOGICI'!G6,"") -> 4294967296 | H8: =IF('DATI LOGICI'!H6<>"",'DATI LOGICI'!H6,"") | I8: =IF('DATI LOGICI'!I6<>"",'DATI LOGICI'!I6,"") -> RW
A9: =IF('DATI LOGICI'!A7<>"",'DATI LOGICI'!A7,"") -> Tipo scheda | B9: =IF('DATI LOGICI'!B7<>"",'DATI LOGICI'!B7,"") -> 0 | C9: =IF('DATI LOGICI'!C7<>"",'DATI LOGICI'!C7,"") -> 4 | D9: =IF('DATI LOGICI'!D7<>"",'DATI LOGICI'!D7,"") -> enum dipendente dalle macchine | E9: =IF('DATI LOGICI'!E7<>"",'DATI LOGICI'!E7,"") | F9: =IF('DATI LOGICI'!F7<>"",'DATI LOGICI'!F7,"") | G9: =IF('DATI LOGICI'!G7<>"",'DATI LOGICI'!G7,"") | H9: =IF('DATI LOGICI'!H7<>"",'DATI LOGICI'!H7,"") | I9: R
A10: =IF('DATI LOGICI'!A8<>"",'DATI LOGICI'!A8,"") -> Stato | B10: =IF('DATI LOGICI'!B8<>"",'DATI LOGICI'!B8,"") -> 0 | C10: =IF('DATI LOGICI'!C8<>"",'DATI LOGICI'!C8,"") -> 5 | D10: =IF('DATI LOGICI'!D8<>"",'DATI LOGICI'!D8,"") -> 3*uint32_t | E10: =IF('DATI LOGICI'!E8<>"",'DATI LOGICI'!E8,"") | F10: =IF('DATI LOGICI'!F8<>"",'DATI LOGICI'!F8,"") | G10: =IF('DATI LOGICI'!G8<>"",'DATI LOGICI'!G8,"") | H10: =IF('DATI LOGICI'!H8<>"",'DATI LOGICI'!H8,"") | I10: =IF('DATI LOGICI'!I8<>"",'DATI LOGICI'!I8,"") -> R
A11: =IF('DATI LOGICI'!A9<>"",'DATI LOGICI'!A9,"") -> Allarmi | B11: =IF('DATI LOGICI'!B9<>"",'DATI LOGICI'!B9,"") -> 0 | C11: =IF('DATI LOGICI'!C9<>"",'DATI LOGICI'!C9,"") -> 6 | D11: =IF('DATI LOGICI'!D9<>"",'DATI LOGICI'!D9,"") -> due word uint16_t bitmapped | E11: =IF('DATI LOGICI'!E9<>"",'DATI LOGICI'!E9,"") | F11: =IF('DATI LOGICI'!F9<>"",'DATI LOGICI'!F9,"") | G11: =IF('DATI LOGICI'!G9<>"",'DATI LOGICI'!G9,"") | H11: =IF('DATI LOGICI'!H9<>"",'DATI LOGICI'!H9,"") | I11: =IF('DATI LOGICI'!I9<>"",'DATI LOGICI'!I9,"") -> R | J11: Log GD
A12: =IF('DATI LOGICI'!A10<>"",'DATI LOGICI'!A10,"") -> Comandi | B12: =IF('DATI LOGICI'!B10<>"",'DATI LOGICI'!B10,"") -> 0 | C12: =IF('DATI LOGICI'!C10<>"",'DATI LOGICI'!C10,"") -> 7 | D12: =IF('DATI LOGICI'!D10<>"",'DATI LOGICI'!D10,"") -> uint16_t | E12: =IF('DATI LOGICI'!E10<>"",'DATI LOGICI'!E10,"") | F12: =IF('DATI LOGICI'!F10<>"",'DATI LOGICI'!F10,"") | G12: =IF('DATI LOGICI'!G10<>"",'DATI LOGICI'!G10,"") | H12: =IF('DATI LOGICI'!H10<>"",'DATI LOGICI'!H10,"") | I12: =IF('DATI LOGICI'!I10<>"",'DATI LOGICI'!I10,"") -> N
A13: =IF('DATI LOGICI'!A11<>"",'DATI LOGICI'!A11,"") -> Temperatura scheda | B13: =IF('DATI LOGICI'!B11<>"",'DATI LOGICI'!B11,"") -> 0 | C13: =IF('DATI LOGICI'!C11<>"",'DATI LOGICI'!C11,"") -> 8 | D13: =IF('DATI LOGICI'!D11<>"",'DATI LOGICI'!D11,"") -> uint16_t | E13: =IF('DATI LOGICI'!E11<>"",'DATI LOGICI'!E11,"") | F13: =IF('DATI LOGICI'!F11<>"",'DATI LOGICI'!F11,"") | G13: =IF('DATI LOGICI'!G11<>"",'DATI LOGICI'!G11,"") | H13: =IF('DATI LOGICI'!H11<>"",'DATI LOGICI'!H11,"") | I13: =IF('DATI LOGICI'!I11<>"",'DATI LOGICI'!I11,"") -> R
A14: =IF('DATI LOGICI'!A12<>"",'DATI LOGICI'!A12,"") -> Secondi lavoro motore parziale | B14: =IF('DATI LOGICI'!B12<>"",'DATI LOGICI'!B12,"") -> 0 | C14: =IF('DATI LOGICI'!C12<>"",'DATI LOGICI'!C12,"") -> 9 | D14: =IF('DATI LOGICI'!D12<>"",'DATI LOGICI'!D12,"") -> uint32_t | E14: =IF('DATI LOGICI'!E12<>"",'DATI LOGICI'!E12,"") | F14: =IF('DATI LOGICI'!F12<>"",'DATI LOGICI'!F12,"") | G14: =IF('DATI LOGICI'!G12<>"",'DATI LOGICI'!G12,"") | H14: =IF('DATI LOGICI'!H12<>"",'DATI LOGICI'!H12,"") | I14: =IF('DATI LOGICI'!I12<>"",'DATI LOGICI'!I12,"") -> RW
A15: =IF('DATI LOGICI'!A13<>"",'DATI LOGICI'!A13,"") -> Secondi lavoro motore totale | B15: =IF('DATI LOGICI'!B13<>"",'DATI LOGICI'!B13,"") -> 0 | C15: =IF('DATI LOGICI'!C13<>"",'DATI LOGICI'!C13,"") -> A | D15: =IF('DATI LOGICI'!D13<>"",'DATI LOGICI'!D13,"") -> uint32_t | E15: =IF('DATI LOGICI'!E13<>"",'DATI LOGICI'!E13,"") | F15: =IF('DATI LOGICI'!F13<>"",'DATI LOGICI'!F13,"") | G15: =IF('DATI LOGICI'!G13<>"",'DATI LOGICI'!G13,"") | H15: =IF('DATI LOGICI'!H13<>"",'DATI LOGICI'!H13,"") | I15: =IF('DATI LOGICI'!I13<>"",'DATI LOGICI'!I13,"") -> RW
A16: =IF('DATI LOGICI'!A14<>"",'DATI LOGICI'!A14,"") -> Cicli complessivi parziale | B16: =IF('DATI LOGICI'!B14<>"",'DATI LOGICI'!B14,"") -> 0 | C16: =IF('DATI LOGICI'!C14<>"",'DATI LOGICI'!C14,"") -> B | D16: =IF('DATI LOGICI'!D14<>"",'DATI LOGICI'!D14,"") -> uint32_t | E16: =IF('DATI LOGICI'!E14<>"",'DATI LOGICI'!E14,"") | F16: =IF('DATI LOGICI'!F14<>"",'DATI LOGICI'!F14,"") | G16: =IF('DATI LOGICI'!G14<>"",'DATI LOGICI'!G14,"") | H16: =IF('DATI LOGICI'!H14<>"",'DATI LOGICI'!H14,"") | I16: =IF('DATI LOGICI'!I14<>"",'DATI LOGICI'!I14,"") -> RW
A17: =IF('DATI LOGICI'!A15<>"",'DATI LOGICI'!A15,"") -> Cicli complessivi totale | B17: =IF('DATI LOGICI'!B15<>"",'DATI LOGICI'!B15,"") -> 0 | C17: =IF('DATI LOGICI'!C15<>"",'DATI LOGICI'!C15,"") -> C | D17: =IF('DATI LOGICI'!D15<>"",'DATI LOGICI'!D15,"") -> uint32_t | E17: =IF('DATI LOGICI'!E15<>"",'DATI LOGICI'!E15,"") | F17: =IF('DATI LOGICI'!F15<>"",'DATI LOGICI'!F15,"") | G17: =IF('DATI LOGICI'!G15<>"",'DATI LOGICI'!G15,"") | H17: =IF('DATI LOGICI'!H15<>"",'DATI LOGICI'!H15,"") | I17: =IF('DATI LOGICI'!I15<>"",'DATI LOGICI'!I15,"") -> RW
A18: =IF('DATI LOGICI'!A16<>"",'DATI LOGICI'!A16,"") -> Cicli completi eseguiti parziale | B18: =IF('DATI LOGICI'!B16<>"",'DATI LOGICI'!B16,"") -> 0 | C18: =IF('DATI LOGICI'!C16<>"",'DATI LOGICI'!C16,"") -> D | D18: =IF('DATI LOGICI'!D16<>"",'DATI LOGICI'!D16,"") -> uint32_t | E18: =IF('DATI LOGICI'!E16<>"",'DATI LOGICI'!E16,"") | F18: =IF('DATI LOGICI'!F16<>"",'DATI LOGICI'!F16,"") | G18: =IF('DATI LOGICI'!G16<>"",'DATI LOGICI'!G16,"") | H18: =IF('DATI LOGICI'!H16<>"",'DATI LOGICI'!H16,"") | I18: =IF('DATI LOGICI'!I16<>"",'DATI LOGICI'!I16,"") -> RW
A19: =IF('DATI LOGICI'!A17<>"",'DATI LOGICI'!A17,"") -> Cicli completi eseguiti totale | B19: =IF('DATI LOGICI'!B17<>"",'DATI LOGICI'!B17,"") -> 0 | C19: =IF('DATI LOGICI'!C17<>"",'DATI LOGICI'!C17,"") -> E | D19: =IF('DATI LOGICI'!D17<>"",'DATI LOGICI'!D17,"") -> uint32_t | E19: =IF('DATI LOGICI'!E17<>"",'DATI LOGICI'!E17,"") | F19: =IF('DATI LOGICI'!F17<>"",'DATI LOGICI'!F17,"") | G19: =IF('DATI LOGICI'!G17<>"",'DATI LOGICI'!G17,"") | H19: =IF('DATI LOGICI'!H17<>"",'DATI LOGICI'!H17,"") | I19: =IF('DATI LOGICI'!I17<>"",'DATI LOGICI'!I17,"") -> RW
A20: =IF('DATI LOGICI'!A18<>"",'DATI LOGICI'!A18,"") -> Livello batteria | B20: =IF('DATI LOGICI'!B18<>"",'DATI LOGICI'!B18,"") -> 0 | C20: =IF('DATI LOGICI'!C18<>"",'DATI LOGICI'!C18,"") -> F | D20: =IF('DATI LOGICI'!D18<>"",'DATI LOGICI'!D18,"") -> uint16_t | E20: =IF('DATI LOGICI'!E18<>"",'DATI LOGICI'!E18,"") | F20: =IF('DATI LOGICI'!F18<>"",'DATI LOGICI'!F18,"") | G20: =IF('DATI LOGICI'!G18<>"",'DATI LOGICI'!G18,"") | H20: =IF('DATI LOGICI'!H18<>"",'DATI LOGICI'!H18,"") | I20: =IF('DATI LOGICI'!I18<>"",'DATI LOGICI'!I18,"") -> R
A21: =IF('DATI LOGICI'!A19<>"",'DATI LOGICI'!A19,"") -> Salute batteria | B21: =IF('DATI LOGICI'!B19<>"",'DATI LOGICI'!B19,"") -> 0 | C21: =IF('DATI LOGICI'!C19<>"",'DATI LOGICI'!C19,"") -> 10 | D21: =IF('DATI LOGICI'!D19<>"",'DATI LOGICI'!D19,"") -> uint16_t | E21: =IF('DATI LOGICI'!E19<>"",'DATI LOGICI'!E19,"") | F21: =IF('DATI LOGICI'!F19<>"",'DATI LOGICI'!F19,"") | G21: =IF('DATI LOGICI'!G19<>"",'DATI LOGICI'!G19,"") | H21: =IF('DATI LOGICI'!H19<>"",'DATI LOGICI'!H19,"") | I21: =IF('DATI LOGICI'!I19<>"",'DATI LOGICI'!I19,"") -> R
A22: =IF('DATI LOGICI'!A20<>"",'DATI LOGICI'!A20,"") -> Cicli batteria | B22: =IF('DATI LOGICI'!B20<>"",'DATI LOGICI'!B20,"") -> 0 | C22: =IF('DATI LOGICI'!C20<>"",'DATI LOGICI'!C20,"") -> 11 | D22: =IF('DATI LOGICI'!D20<>"",'DATI LOGICI'!D20,"") -> uint16_t | E22: =IF('DATI LOGICI'!E20<>"",'DATI LOGICI'!E20,"") | F22: =IF('DATI LOGICI'!F20<>"",'DATI LOGICI'!F20,"") | G22: =IF('DATI LOGICI'!G20<>"",'DATI LOGICI'!G20,"") | H22: =IF('DATI LOGICI'!H20<>"",'DATI LOGICI'!H20,"") | I22: =IF('DATI LOGICI'!I20<>"",'DATI LOGICI'!I20,"") -> R
A23: =IF('DATI LOGICI'!A21<>"",'DATI LOGICI'!A21,"") -> Temperatura batteria | B23: =IF('DATI LOGICI'!B21<>"",'DATI LOGICI'!B21,"") -> 0 | C23: =IF('DATI LOGICI'!C21<>"",'DATI LOGICI'!C21,"") -> 12 | D23: =IF('DATI LOGICI'!D21<>"",'DATI LOGICI'!D21,"") -> int16_t | E23: =IF('DATI LOGICI'!E21<>"",'DATI LOGICI'!E21,"") | F23: =IF('DATI LOGICI'!F21<>"",'DATI LOGICI'!F21,"") | G23: =IF('DATI LOGICI'!G21<>"",'DATI LOGICI'!G21,"") | H23: =IF('DATI LOGICI'!H21<>"",'DATI LOGICI'!H21,"") | I23: =IF('DATI LOGICI'!I21<>"",'DATI LOGICI'!I21,"") -> R
... A27: =IF('DATI LOGICI'!A25<>"",'DATI LOGICI'!A25,"") -> Stato uscite fisiche | B27: =IF('DATI LOGICI'!B25<>"",'DATI LOGICI'!B25,"") -> 0 | C27: =IF('DATI LOGICI'!C25<>"",'DATI LOGICI'!C25,"") -> 16 | D27: =IF('DATI LOGICI'!D25<>"",'DATI LOGICI'!D25,"") -> uint32_t | E27: =IF('DATI LOGICI'!E25<>"",'DATI LOGICI'!E25,"") | F27: =IF('DATI LOGICI'!F25<>"",'DATI LOGICI'!F25,"") | G27: =IF('DATI LOGICI'!G25<>"",'DATI LOGICI'!G25,"") | H27: =IF('DATI LOGICI'!H25<>"",'DATI LOGICI'!H25,"") | I27: =IF('DATI LOGICI'!I25<>"",'DATI LOGICI'!I25,"") -> R
A29: DATI LOGICI TASTIERA
A30: Foto Tasti | B30: 80 | C30: =DEC2HEX(0) -> 0 | D30: uint8_t | I30: R | K30: Variabile logica gestita dalla tastiera esterna
A31: Stato sistema (non più usato) | B31: 80 | C31: =DEC2HEX(HEX2DEC(C30)+1) -> 1 | D31: bool | F31: 0 | G31: 1 | I31: R | K31: 0 = piano fermo, 1 = piano in movimento
A32: Comando Led Verde | B32: 80 | C32: 2 | D32: uint32_t | E32: 255255255255 | F32: 0 | G32: 255255255255 | I32: RW | K32: BYTE 0: Attivazione led, numero ripetizioni bit8: 1=Led acceso fisso bit7: 1=Led lampeggiante bit 6: 1= Single shot, 0 =loop bit 5-0: Numero di lampeggi per ogni ciclo BYTE 1: Tempo di on del singolo lampeggio (in 4ms) BYTE 2: Tempo di off del singolo lampeggio (in 4ms) BYTE 3: Tempo di pausa tra i gruppi di lampeggi (in 4ms)
A33: Comando Led Rosso | B33: 80 | C33: 3 | D33: uint32_t | E33: 255255255255 | F33: 0 | G33: 255255255255 | I33: RW | K33: BYTE 0: Attivazione led, numero ripetizioni bit8: 1=Led acceso fisso bit7: 1=Led lampeggiante bit 6: 1= Single shot, 0 =loop bit 5-0: Numero di lampeggi per ogni ciclo BYTE 1: Tempo di on del singolo lampeggio (in 4ms) BYTE 2: Tempo di off del singolo lampeggio (in 4ms) BYTE 3: Tempo di pausa tra i gruppi di lampeggi (in 4ms)
A34: Comando Buzzer | B34: 80 | C34: 4 | D34: uint32_t | E34: 255255255255 | F34: 0 | G34: 255255255255 | I34: RW | K34: BYTE 0: Attivazione buzzer, numero ripetizioni bit8: 1=Buzzer acceso fisso bit7: 1=Buzzer lampeggiante bit 6-0: Numero di lampeggi per ogni ciclo BYTE 1: Tempo di on del singolo suono (in 4ms) BYTE 2: Tempo di off del singolo suono (in 4ms) BYTE 3: Tempo di pausa tra i gruppi di suoni (in 4ms)

Sheet DATI LOGICI HMI SPYKE
A1: INDIRIZZI SCHEDE A CUI SI APPLICA QUESTO DIZIONARIO
A2: 0x00050201
A3: HMI SPYKE | B3: INDIRIZZO H+L (hex) | D3: TIPO | E3: FORMATO | F3: MINIMO | G3: MASSIMO | H3: UNITA' DI MISURA | I3: R/W | J3: Uso | K3: Significato | L3: Ubicazione in App | M3: Nome in App | N3: Aspetto in App | O3: Effetti in App
A4: DATI STANDARD
A5: =IF('DATI LOGICI'!A3<>"",'DATI LOGICI'!A3,"") -> Firmware macchina | B5: =IF('DATI LOGICI'!B3<>"",'DATI LOGICI'!B3,"") -> 0 | C5: =IF('DATI LOGICI'!C3<>"",'DATI LOGICI'!C3,"") -> 0 | D5: =IF('DATI LOGICI'!D3<>"",'DATI LOGICI'!D3,"") -> uint16_t | E5: =IF('DATI LOGICI'!E3<>"",'DATI LOGICI'!E3,"") -> 255.255 | F5: =IF('DATI LOGICI'!F3<>"",'DATI LOGICI'!F3,"") -> 0 | G5: =IF('DATI LOGICI'!G3<>"",'DATI LOGICI'!G3,"") -> 255.255 | H5: =IF('DATI LOGICI'!H3<>"",'DATI LOGICI'!H3,"") | I5: =IF('DATI LOGICI'!I3<>"",'DATI LOGICI'!I3,"") -> R
A6: =IF('DATI LOGICI'!A4<>"",'DATI LOGICI'!A4,"") -> Firmware scheda | B6: =IF('DATI LOGICI'!B4<>"",'DATI LOGICI'!B4,"") -> 0 | C6: =IF('DATI LOGICI'!C4<>"",'DATI LOGICI'!C4,"") -> 1 | D6: =IF('DATI LOGICI'!D4<>"",'DATI LOGICI'!D4,"") -> uint16_t | E6: =IF('DATI LOGICI'!E4<>"",'DATI LOGICI'!E4,"") -> 255.255 | F6: =IF('DATI LOGICI'!F4<>"",'DATI LOGICI'!F4,"") -> 0 | G6: =IF('DATI LOGICI'!G4<>"",'DATI LOGICI'!G4,"") -> 255.255 | H6: =IF('DATI LOGICI'!H4<>"",'DATI LOGICI'!H4,"") | I6: =IF('DATI LOGICI'!I4<>"",'DATI LOGICI'!I4,"") -> R
A7: =IF('DATI LOGICI'!A5<>"",'DATI LOGICI'!A5,"") -> Modello | B7: =IF('DATI LOGICI'!B5<>"",'DATI LOGICI'!B5,"") -> 0 | C7: =IF('DATI LOGICI'!C5<>"",'DATI LOGICI'!C5,"") -> 2 | D7: =IF('DATI LOGICI'!D5<>"",'DATI LOGICI'!D5,"") -> String[20] | E7: =IF('DATI LOGICI'!E5<>"",'DATI LOGICI'!E5,"") | F7: =IF('DATI LOGICI'!F5<>"",'DATI LOGICI'!F5,"") | G7: =IF('DATI LOGICI'!G5<>"",'DATI LOGICI'!G5,"") | H7: =IF('DATI LOGICI'!H5<>"",'DATI LOGICI'!H5,"") | I7: =IF('DATI LOGICI'!I5<>"",'DATI LOGICI'!I5,"") -> R
A8: =IF('DATI LOGICI'!A6<>"",'DATI LOGICI'!A6,"") -> Matricola | B8: =IF('DATI LOGICI'!B6<>"",'DATI LOGICI'!B6,"") -> 0 | C8: =IF('DATI LOGICI'!C6<>"",'DATI LOGICI'!C6,"") -> 3 | D8: =IF('DATI LOGICI'!D6<>"",'DATI LOGICI'!D6,"") -> uint32_t | E8: =IF('DATI LOGICI'!E6<>"",'DATI LOGICI'!E6,"") | F8: =IF('DATI LOGICI'!F6<>"",'DATI LOGICI'!F6,"") -> 0 | G8: =IF('DATI LOGICI'!G6<>"",'DATI LOGICI'!G6,"") -> 4294967296 | H8: =IF('DATI LOGICI'!H6<>"",'DATI LOGICI'!H6,"") | I8: =IF('DATI LOGICI'!I6<>"",'DATI LOGICI'!I6,"") -> RW
A9: =IF('DATI LOGICI'!A7<>"",'DATI LOGICI'!A7,"") -> Tipo scheda | B9: =IF('DATI LOGICI'!B7<>"",'DATI LOGICI'!B7,"") -> 0 | C9: =IF('DATI LOGICI'!C7<>"",'DATI LOGICI'!C7,"") -> 4 | D9: =IF('DATI LOGICI'!D7<>"",'DATI LOGICI'!D7,"") -> enum dipendente dalle macchine | E9: =IF('DATI LOGICI'!E7<>"",'DATI LOGICI'!E7,"") | F9: =IF('DATI LOGICI'!F7<>"",'DATI LOGICI'!F7,"") | G9: =IF('DATI LOGICI'!G7<>"",'DATI LOGICI'!G7,"") | H9: =IF('DATI LOGICI'!H7<>"",'DATI LOGICI'!H7,"") | I9: =IF('DATI LOGICI'!I7<>"",'DATI LOGICI'!I7,"") -> N
A10: =IF('DATI LOGICI'!A8<>"",'DATI LOGICI'!A8,"") -> Stato | B10: =IF('DATI LOGICI'!B8<>"",'DATI LOGICI'!B8,"") -> 0 | C10: =IF('DATI LOGICI'!C8<>"",'DATI LOGICI'!C8,"") -> 5 | D10: =IF('DATI LOGICI'!D8<>"",'DATI LOGICI'!D8,"") -> 3*uint32_t | E10: =IF('DATI LOGICI'!E8<>"",'DATI LOGICI'!E8,"") | F10: =IF('DATI LOGICI'!F8<>"",'DATI LOGICI'!F8,"") | G10: =IF('DATI LOGICI'!G8<>"",'DATI LOGICI'!G8,"") | H10: =IF('DATI LOGICI'!H8<>"",'DATI LOGICI'!H8,"") | I10: =IF('DATI LOGICI'!I8<>"",'DATI LOGICI'!I8,"") -> R | K10: Macchina a stati
A11: =IF('DATI LOGICI'!A9<>"",'DATI LOGICI'!A9,"") -> Allarmi | B11: =IF('DATI LOGICI'!B9<>"",'DATI LOGICI'!B9,"") -> 0 | C11: =IF('DATI LOGICI'!C9<>"",'DATI LOGICI'!C9,"") -> 6 | D11: =IF('DATI LOGICI'!D9<>"",'DATI LOGICI'!D9,"") -> due word uint16_t bitmapped | E11: =IF('DATI LOGICI'!E9<>"",'DATI LOGICI'!E9,"") | F11: =IF('DATI LOGICI'!F9<>"",'DATI LOGICI'!F9,"") | G11: =IF('DATI LOGICI'!G9<>"",'DATI LOGICI'!G9,"") | H11: =IF('DATI LOGICI'!H9<>"",'DATI LOGICI'!H9,"") | I11: =IF('DATI LOGICI'!I9<>"",'DATI LOGICI'!I9,"") -> R | J11: Log GD | K11: Gli allarmi vengono raccolti da tutte le schede periferiche e raggruppati in un unico gruppo di variabili. Allarmi Errore CAN Tensione troppo bassa Errore touch Errore sensore 10G (se vedo Vricarica senza vedere 10G) Sovraccarico celle (quando sono a tensione batteria massima ma ho ancora corrente) è un errore o un warning? Avvisi Tensione bassa NFC non presente (se barellino agganciato) NFC non riconosciuto (se barellino agganciato) Barellino non agganciato (se NFC presente) Mancanza di Vricarica con 10G agganciato Celle sbilanciate (quando sono in ricarica ma non ho corrente di ricarica) Perdita di stabilità della barella (da giroscopio) Incoerenza leva/pulsante in carico Incoerenza leva/pulsante in scarico
A12: =IF('DATI LOGICI'!A10<>"",'DATI LOGICI'!A10,"") -> Comandi | B12: =IF('DATI LOGICI'!B10<>"",'DATI LOGICI'!B10,"") -> 0 | C12: =IF('DATI LOGICI'!C10<>"",'DATI LOGICI'!C10,"") -> 7 | D12: =IF('DATI LOGICI'!D10<>"",'DATI LOGICI'!D10,"") -> uint16_t | E12: =IF('DATI LOGICI'!E10<>"",'DATI LOGICI'!E10,"") | F12: =IF('DATI LOGICI'!F10<>"",'DATI LOGICI'!F10,"") | G12: =IF('DATI LOGICI'!G10<>"",'DATI LOGICI'!G10,"") | H12: =IF('DATI LOGICI'!H10<>"",'DATI LOGICI'!H10,"") | I12: =IF('DATI LOGICI'!I10<>"",'DATI LOGICI'!I10,"") -> N
A13: =IF('DATI LOGICI'!A11<>"",'DATI LOGICI'!A11,"") -> Temperatura scheda | B13: =IF('DATI LOGICI'!B11<>"",'DATI LOGICI'!B11,"") -> 0 | C13: =IF('DATI LOGICI'!C11<>"",'DATI LOGICI'!C11,"") -> 8 | D13: =IF('DATI LOGICI'!D11<>"",'DATI LOGICI'!D11,"") -> uint16_t | E13: =IF('DATI LOGICI'!E11<>"",'DATI LOGICI'!E11,"") | F13: =IF('DATI LOGICI'!F11<>"",'DATI LOGICI'!F11,"") | G13: =IF('DATI LOGICI'!G11<>"",'DATI LOGICI'!G11,"") | H13: =IF('DATI LOGICI'!H11<>"",'DATI LOGICI'!H11,"") | I13: =IF('DATI LOGICI'!I11<>"",'DATI LOGICI'!I11,"") -> R
A14: =IF('DATI LOGICI'!A12<>"",'DATI LOGICI'!A12,"") -> Secondi lavoro motore parziale | B14: =IF('DATI LOGICI'!B12<>"",'DATI LOGICI'!B12,"") -> 0 | C14: =IF('DATI LOGICI'!C12<>"",'DATI LOGICI'!C12,"") -> 9 | D14: =IF('DATI LOGICI'!D12<>"",'DATI LOGICI'!D12,"") -> uint32_t | E14: =IF('DATI LOGICI'!E12<>"",'DATI LOGICI'!E12,"") | F14: =IF('DATI LOGICI'!F12<>"",'DATI LOGICI'!F12,"") | G14: =IF('DATI LOGICI'!G12<>"",'DATI LOGICI'!G12,"") | H14: =IF('DATI LOGICI'!H12<>"",'DATI LOGICI'!H12,"") | I14: =IF('DATI LOGICI'!I12<>"",'DATI LOGICI'!I12,"") -> RW
A15: =IF('DATI LOGICI'!A13<>"",'DATI LOGICI'!A13,"") -> Secondi lavoro motore totale | B15: =IF('DATI LOGICI'!B13<>"",'DATI LOGICI'!B13,"") -> 0 | C15: =IF('DATI LOGICI'!C13<>"",'DATI LOGICI'!C13,"") -> A | D15: =IF('DATI LOGICI'!D13<>"",'DATI LOGICI'!D13,"") -> uint32_t | E15: =IF('DATI LOGICI'!E13<>"",'DATI LOGICI'!E13,"") | F15: =IF('DATI LOGICI'!F13<>"",'DATI LOGICI'!F13,"") | G15: =IF('DATI LOGICI'!G13<>"",'DATI LOGICI'!G13,"") | H15: =IF('DATI LOGICI'!H13<>"",'DATI LOGICI'!H13,"") | I15: =IF('DATI LOGICI'!I13<>"",'DATI LOGICI'!I13,"") -> RW
A16: =IF('DATI LOGICI'!A14<>"",'DATI LOGICI'!A14,"") -> Cicli complessivi parziale | B16: =IF('DATI LOGICI'!B14<>"",'DATI LOGICI'!B14,"") -> 0 | C16: =IF('DATI LOGICI'!C14<>"",'DATI LOGICI'!C14,"") -> B | D16: =IF('DATI LOGICI'!D14<>"",'DATI LOGICI'!D14,"") -> uint32_t | E16: =IF('DATI LOGICI'!E14<>"",'DATI LOGICI'!E14,"") | F16: =IF('DATI LOGICI'!F14<>"",'DATI LOGICI'!F14,"") | G16: =IF('DATI LOGICI'!G14<>"",'DATI LOGICI'!G14,"") | H16: =IF('DATI LOGICI'!H14<>"",'DATI LOGICI'!H14,"") | I16: =IF('DATI LOGICI'!I14<>"",'DATI LOGICI'!I14,"") -> RW | J16: Log | K16: Numero agganci al 10G resettabile (il segnale arriva dal Gateway ma l'elaborazione come significato e funzione avviene qui)
A17: =IF('DATI LOGICI'!A15<>"",'DATI LOGICI'!A15,"") -> Cicli complessivi totale | B17: =IF('DATI LOGICI'!B15<>"",'DATI LOGICI'!B15,"") -> 0 | C17: =IF('DATI LOGICI'!C15<>"",'DATI LOGICI'!C15,"") -> C | D17: =IF('DATI LOGICI'!D15<>"",'DATI LOGICI'!D15,"") -> uint32_t | E17: =IF('DATI LOGICI'!E15<>"",'DATI LOGICI'!E15,"") | F17: =IF('DATI LOGICI'!F15<>"",'DATI LOGICI'!F15,"") | G17: =IF('DATI LOGICI'!G15<>"",'DATI LOGICI'!G15,"") | H17: =IF('DATI LOGICI'!H15<>"",'DATI LOGICI'!H15,"") | I17: =IF('DATI LOGICI'!I15<>"",'DATI LOGICI'!I15,"") -> RW | J17: Log | K17: Numero agganci al 10G non resettabile
A18: =IF('DATI LOGICI'!A16<>"",'DATI LOGICI'!A16,"") -> Cicli completi eseguiti parziale | B18: =IF('DATI LOGICI'!B16<>"",'DATI LOGICI'!B16,"") -> 0 | C18: =IF('DATI LOGICI'!C16<>"",'DATI LOGICI'!C16,"") -> D | D18: =IF('DATI LOGICI'!D16<>"",'DATI LOGICI'!D16,"") -> uint32_t | E18: =IF('DATI LOGICI'!E16<>"",'DATI LOGICI'!E16,"") | F18: =IF('DATI LOGICI'!F16<>"",'DATI LOGICI'!F16,"") | G18: =IF('DATI LOGICI'!G16<>"",'DATI LOGICI'!G16,"") | H18: =IF('DATI LOGICI'!H16<>"",'DATI LOGICI'!H16,"") | I18: =IF('DATI LOGICI'!I16<>"",'DATI LOGICI'!I16,"") -> RW | J18: Log | K18: Numero agganci al 10G resettabile dopo ciclo Sherpa?
A19: =IF('DATI LOGICI'!A17<>"",'DATI LOGICI'!A17,"") -> Cicli completi eseguiti totale | B19: =IF('DATI LOGICI'!B17<>"",'DATI LOGICI'!B17,"") -> 0 | C19: =IF('DATI LOGICI'!C17<>"",'DATI LOGICI'!C17,"") -> E | D19: =IF('DATI LOGICI'!D17<>"",'DATI LOGICI'!D17,"") -> uint32_t | E19: =IF('DATI LOGICI'!E17<>"",'DATI LOGICI'!E17,"") | F19: =IF('DATI LOGICI'!F17<>"",'DATI LOGICI'!F17,"") | G19: =IF('DATI LOGICI'!G17<>"",'DATI LOGICI'!G17,"") | H19: =IF('DATI LOGICI'!H17<>"",'DATI LOGICI'!H17,"") | I19: =IF('DATI LOGICI'!I17<>"",'DATI LOGICI'!I17,"") -> RW | J19: Log | K19: Numero agganci al 10G non resettabile dopo ciclo Sherpa?
A20: =IF('DATI LOGICI'!A18<>"",'DATI LOGICI'!A18,"") -> Livello batteria | B20: =IF('DATI LOGICI'!B18<>"",'DATI LOGICI'!B18,"") -> 0 | C20: =IF('DATI LOGICI'!C18<>"",'DATI LOGICI'!C18,"") -> F | D20: =IF('DATI LOGICI'!D18<>"",'DATI LOGICI'!D18,"") -> uint16_t | E20: =IF('DATI LOGICI'!E18<>"",'DATI LOGICI'!E18,"") | F20: =IF('DATI LOGICI'!F18<>"",'DATI LOGICI'!F18,"") | G20: =IF('DATI LOGICI'!G18<>"",'DATI LOGICI'!G18,"") | H20: =IF('DATI LOGICI'!H18<>"",'DATI LOGICI'!H18,"") | I20: =IF('DATI LOGICI'!I18<>"",'DATI LOGICI'!I18,"") -> R
A21: =IF('DATI LOGICI'!A19<>"",'DATI LOGICI'!A19,"") -> Salute batteria | B21: =IF('DATI LOGICI'!B19<>"",'DATI LOGICI'!B19,"") -> 0 | C21: =IF('DATI LOGICI'!C19<>"",'DATI LOGICI'!C19,"") -> 10 | D21: =IF('DATI LOGICI'!D19<>"",'DATI LOGICI'!D19,"") -> uint16_t | E21: =IF('DATI LOGICI'!E19<>"",'DATI LOGICI'!E19,"") | F21: =IF('DATI LOGICI'!F19<>"",'DATI LOGICI'!F19,"") | G21: =IF('DATI LOGICI'!G19<>"",'DATI LOGICI'!G19,"") | H21: =IF('DATI LOGICI'!H19<>"",'DATI LOGICI'!H19,"") | I21: =IF('DATI LOGICI'!I19<>"",'DATI LOGICI'!I19,"") -> R
A22: =IF('DATI LOGICI'!A20<>"",'DATI LOGICI'!A20,"") -> Cicli batteria | B22: =IF('DATI LOGICI'!B20<>"",'DATI LOGICI'!B20,"") -> 0 | C22: =IF('DATI LOGICI'!C20<>"",'DATI LOGICI'!C20,"") -> 11 | D22: =IF('DATI LOGICI'!D20<>"",'DATI LOGICI'!D20,"") -> uint16_t | E22: =IF('DATI LOGICI'!E20<>"",'DATI LOGICI'!E20,"") | F22: =IF('DATI LOGICI'!F20<>"",'DATI LOGICI'!F20,"") | G22: =IF('DATI LOGICI'!G20<>"",'DATI LOGICI'!G20,"") | H22: =IF('DATI LOGICI'!H20<>"",'DATI LOGICI'!H20,"") | I22: =IF('DATI LOGICI'!I20<>"",'DATI LOGICI'!I20,"") -> R
A23: =IF('DATI LOGICI'!A21<>"",'DATI LOGICI'!A21,"") -> Temperatura batteria | B23: =IF('DATI LOGICI'!B21<>"",'DATI LOGICI'!B21,"") -> 0 | C23: =IF('DATI LOGICI'!C21<>"",'DATI LOGICI'!C21,"") -> 12 | D23: =IF('DATI LOGICI'!D21<>"",'DATI LOGICI'!D21,"") -> int16_t | E23: =IF('DATI LOGICI'!E21<>"",'DATI LOGICI'!E21,"") | F23: =IF('DATI LOGICI'!F21<>"",'DATI LOGICI'!F21,"") | G23: =IF('DATI LOGICI'!G21<>"",'DATI LOGICI'!G21,"") | H23: =IF('DATI LOGICI'!H21<>"",'DATI LOGICI'!H21,"") | I23: =IF('DATI LOGICI'!I21<>"",'DATI LOGICI'!I21,"") -> R
A24: =IF('DATI LOGICI'!A22<>"",'DATI LOGICI'!A22,"") -> BatteryFirmware | B24: =IF('DATI LOGICI'!B22<>"",'DATI LOGICI'!B22,"") -> 0 | C24: =IF('DATI LOGICI'!C22<>"",'DATI LOGICI'!C22,"") -> 13 | D24: =IF('DATI LOGICI'!D22<>"",'DATI LOGICI'!D22,"") -> uint32_t | E24: =IF('DATI LOGICI'!E22<>"",'DATI LOGICI'!E22,"") | F24: =IF('DATI LOGICI'!F22<>"",'DATI LOGICI'!F22,"") | G24: =IF('DATI LOGICI'!G22<>"",'DATI LOGICI'!G22,"") | H24: =IF('DATI LOGICI'!H22<>"",'DATI LOGICI'!H22,"") | I24: =IF('DATI LOGICI'!I22<>"",'DATI LOGICI'!I22,"") -> R
A25: =IF('DATI LOGICI'!A23<>"",'DATI LOGICI'!A23,"") -> BatterySerial | B25: =IF('DATI LOGICI'!B23<>"",'DATI LOGICI'!B23,"") -> 0 | C25: =IF('DATI LOGICI'!C23<>"",'DATI LOGICI'!C23,"") -> 14 | D25: =IF('DATI LOGICI'!D23<>"",'DATI LOGICI'!D23,"") -> uint32_t | E25: =IF('DATI LOGICI'!E23<>"",'DATI LOGICI'!E23,"") | F25: =IF('DATI LOGICI'!F23<>"",'DATI LOGICI'!F23,"") | G25: =IF('DATI LOGICI'!G23<>"",'DATI LOGICI'!G23,"") | H25: =IF('DATI LOGICI'!H23<>"",'DATI LOGICI'!H23,"") | I25: =IF('DATI LOGICI'!I23<>"",'DATI LOGICI'!I23,"") -> R
